<mujoco model="Bot1">
  <compiler angle="radian" meshdir="./" />
  
  
  <option timestep="0.002" iterations="50" solver="Newton" tolerance="1e-10">
    <flag contact="enable" gravity="enable" />
  </option>

  
  <default>
    <joint solimplimit="0.999 0.999 0.001" solreflimit="0.005 1" armature="0.01" />
    
    <geom friction="1.5 0.005 0.001" solimp="0.95 0.99 0.001" solref="0.002 1" condim="4" />
  </default>

  <asset>
    <mesh name="part_1" content_type="model/stl" file="part_1.stl" />
    <mesh name="part_1__2" content_type="model/stl" file="part_1__2.stl" />
    <mesh name="part_1__3" content_type="model/stl" file="part_1__3.stl" />
    <mesh name="part_1__4" content_type="model/stl" file="part_1__4.stl" />
    
    <texture name="grid" type="2d" builtin="checker" width="512" height="512" rgb1="0.7 0.8 0.7" rgb2="0.6 0.7 0.6" />
    <material name="grid_mat" texture="grid" texrepeat="20 20" />
  </asset>

  <worldbody>
    
    <geom name="floor" type="plane" size="10 10 0.1" material="grid_mat" friction="1.5 0.01 0.001" />
    
    <body name="part_1" pos="0 0 0.2">
      <inertial pos="0.0209601 0.0241499 0.0199273" quat="0.5 0.5 -0.5 0.5" mass="0.552084" diaginertia="0.00201256 0.0010312 0.0010312" />
      <joint name="floor_to_base" type="free" />
      
      <geom pos="-0.0290399 -0.0153501 0.0106225" quat="1 5.21775e-08 -2.02329e-09 1.35415e-08" type="mesh" rgba="0.25098 0.25098 0.25098 1" mesh="part_1" contype="0" conaffinity="0" />
      
      <body name="part_1_2" pos="-0.063914 -0.0607244 -0.00112728" quat="0.382923 0.21134 0.0847142 -0.895282">
        <inertial pos="0.0508216 0.00300079 -0.0201979" quat="0.28265 0.663346 0.272142 0.637197" mass="0.139372" diaginertia="0.000187026 0.000186955 2.81071e-05" />
        <joint limited="true" name="sh_roll_1" pos="0 0 0" axis="0 0 1" range="-2.22431 2.10411" />
        <geom pos="-0.595484 -1.2957 0.863499" quat="1.32679e-06 1 0 0" type="mesh" rgba="0.25098 0.25098 0.25098 1" mesh="part_1__2" contype="0" conaffinity="0" />
        <body name="part_1_3" pos="0.1016 -0.0172 -0.0172" quat="-0.487469 0.487469 0.512225 0.512224">
          <inertial pos="0.0786937 -0.0129147 0.0184042" quat="0.466512 0.502695 0.4988 0.529964" mass="0.191635" diaginertia="0.000252901 0.000249902 5.35798e-05" />
          <joint limited="true" name="sh_yaw_1" pos="0 0 0" axis="0 0 1" range="-0.0202957 2.99912" />
          <geom pos="-0.600864 0.882908 1.34578" quat="1.32679e-06 1 0 0" type="mesh" rgba="0.25098 0.25098 0.25098 1" mesh="part_1__3" contype="0" conaffinity="0" />
          <body name="part_1_4" pos="0.1253 0 -0.0007">
            <inertial pos="-0.0423193 0.0357184 0.0189022" quat="0.590331 0.590316 0.389231 0.389275" mass="0.0518909" diaginertia="5.92899e-05 5.27497e-05 1.31168e-05" />
            <joint limited="true" name="kn_yaw_1" pos="0 0 0" axis="0 0 1" range="-1.8675 0" />
            <geom pos="0 0 -0.004" quat="0.566404 0 0 -0.824127" type="mesh" rgba="0.25098 0.25098 0.25098 1" mesh="part_1__4" contype="0" conaffinity="0" />
          <geom name="col_part_1_4_0" type="sphere" size="0.001" pos="-0.1395 0.0544 0.0191" rgba="0 1 0 0.5" /><geom name="col_part_1_4_1" type="sphere" size="0.001" pos="-0.1397 0.0545 0.0191" rgba="0 1 0 0.5" /><geom name="col_part_1_4_11" type="sphere" size="0.001" pos="-0.1399 0.0539 0.0196" rgba="0 1 0 0.5" /><geom name="col_part_1_4_20" type="sphere" size="0.001" pos="-0.0684 0.0531 0.0313" rgba="0 1 0 0.5" /><geom name="col_part_1_4_21" type="sphere" size="0.001" pos="0.0109 0.0268 0.0418" rgba="0 1 0 0.5" /><geom name="col_part_1_4_40" type="sphere" size="0.001" pos="-0.1398 0.0539 0.0183" rgba="0 1 0 0.5" /><geom name="col_part_1_4_41" type="sphere" size="0.001" pos="-0.1401 0.0535 0.0187" rgba="0 1 0 0.5" /><geom name="col_part_1_4_93" type="sphere" size="0.001" pos="-0.1401 0.0535 0.0196" rgba="0 1 0 0.5" /><geom name="col_part_1_4_117" type="sphere" size="0.001" pos="-0.1394 0.0545 0.0188" rgba="0 1 0 0.5" /><geom name="col_part_1_4_118" type="sphere" size="0.001" pos="-0.1395 0.0547 0.0187" rgba="0 1 0 0.5" /><geom name="col_part_1_4_119" type="sphere" size="0.001" pos="-0.0886 0.0556 0.0098" rgba="0 1 0 0.5" /><geom name="col_part_1_4_120" type="sphere" size="0.001" pos="-0.0755 0.0542 0.0076" rgba="0 1 0 0.5" /><geom name="col_part_1_4_121" type="sphere" size="0.001" pos="-0.0545 0.0504 0.0040" rgba="0 1 0 0.5" /><geom name="col_part_1_4_122" type="sphere" size="0.001" pos="-0.0545 0.0505 0.0040" rgba="0 1 0 0.5" /><geom name="col_part_1_4_123" type="sphere" size="0.001" pos="-0.0345 0.0451 0.0005" rgba="0 1 0 0.5" /><geom name="col_part_1_4_124" type="sphere" size="0.001" pos="-0.0221 0.0409 -0.0018" rgba="0 1 0 0.5" /><geom name="col_part_1_4_125" type="sphere" size="0.001" pos="-0.0108 0.0363 -0.0038" rgba="0 1 0 0.5" /><geom name="col_part_1_4_126" type="sphere" size="0.001" pos="0.0110 0.0271 -0.0040" rgba="0 1 0 0.5" /></body>
        </body>
      </body>
      <body name="part_1_5" pos="0.105834 -0.0607243 -0.00112728" quat="0.897395 0.0858871 0.210866 -0.377943">
        <inertial pos="0.0508216 0.00300079 -0.0201979" quat="0.28265 0.663346 0.272142 0.637197" mass="0.139372" diaginertia="0.000187026 0.000186955 2.81071e-05" />
        <joint limited="true" name="sh_roll_2" pos="0 0 0" axis="0 0 1" range="-2.1763 2.12593" />
        <geom pos="-0.595484 -1.2957 0.863499" quat="1.32679e-06 1 0 0" type="mesh" rgba="0.25098 0.25098 0.25098 1" mesh="part_1__2" contype="0" conaffinity="0" />
        <body name="part_1_6" pos="0.1016 -0.0172 -0.0172" quat="-0.486859 0.486859 0.512805 0.512804">
          <inertial pos="0.0786937 -0.0129147 0.0184042" quat="0.466512 0.502695 0.4988 0.529964" mass="0.191635" diaginertia="0.000252901 0.000249902 5.35798e-05" />
          <joint limited="true" name="sh_yaw_2" pos="0 0 0" axis="0 0 1" range="-0.00046306 3.01728" />
          <geom pos="-0.600864 0.882908 1.34578" quat="1.32679e-06 1 0 0" type="mesh" rgba="0.25098 0.25098 0.25098 1" mesh="part_1__3" contype="0" conaffinity="0" />
          <body name="part_1_7" pos="0.1253 0 -0.0007" quat="0.572069 0 0 -0.820205">
            <inertial pos="-0.0181801 -0.0523088 0.0189022" quat="0.706958 0.706995 -0.0135554 -0.0135832" mass="0.0518909" diaginertia="5.929e-05 5.27497e-05 1.31167e-05" />
            <joint limited="true" name="kn_yaw_2" pos="0 0 0" axis="0 0 1" range="-1.89874 0.00367303" />
            <geom pos="0 0 -0.004" quat="1 0 0 0" type="mesh" rgba="0.25098 0.25098 0.25098 1" mesh="part_1__4" contype="0" conaffinity="0" />
          <geom name="col_part_1_7_2" type="sphere" size="0.001" pos="-0.0007 -0.1496 0.0187" rgba="0 1 0 0.5" /><geom name="col_part_1_7_12" type="sphere" size="0.001" pos="-0.0291 0.0006 0.0418" rgba="0 1 0 0.5" /><geom name="col_part_1_7_29" type="sphere" size="0.001" pos="0.0018 -0.1430 0.0174" rgba="0 1 0 0.5" /><geom name="col_part_1_7_31" type="sphere" size="0.001" pos="0.0012 -0.1447 0.0179" rgba="0 1 0 0.5" /><geom name="col_part_1_7_33" type="sphere" size="0.001" pos="0.0005 -0.1464 0.0184" rgba="0 1 0 0.5" /><geom name="col_part_1_7_35" type="sphere" size="0.001" pos="-0.0000 -0.1480 0.0189" rgba="0 1 0 0.5" /><geom name="col_part_1_7_42" type="sphere" size="0.001" pos="-0.0001 -0.1490 0.0193" rgba="0 1 0 0.5" /><geom name="col_part_1_7_43" type="sphere" size="0.001" pos="0.0000 -0.1496 0.0196" rgba="0 1 0 0.5" /><geom name="col_part_1_7_54" type="sphere" size="0.001" pos="0.0054 -0.1363 0.0184" rgba="0 1 0 0.5" /><geom name="col_part_1_7_55" type="sphere" size="0.001" pos="0.0039 -0.1397 0.0186" rgba="0 1 0 0.5" /><geom name="col_part_1_7_56" type="sphere" size="0.001" pos="0.0023 -0.1428 0.0187" rgba="0 1 0 0.5" /><geom name="col_part_1_7_57" type="sphere" size="0.001" pos="0.0008 -0.1459 0.0188" rgba="0 1 0 0.5" /><geom name="col_part_1_7_58" type="sphere" size="0.001" pos="-0.0005 -0.1490 0.0189" rgba="0 1 0 0.5" /><geom name="col_part_1_7_83" type="sphere" size="0.001" pos="-0.0285 0.0006 0.0416" rgba="0 1 0 0.5" /><geom name="col_part_1_7_84" type="sphere" size="0.001" pos="-0.0303 -0.0375 0.0390" rgba="0 1 0 0.5" /><geom name="col_part_1_7_102" type="sphere" size="0.001" pos="0.0114 -0.1297 0.0203" rgba="0 1 0 0.5" /><geom name="col_part_1_7_105" type="sphere" size="0.001" pos="0.0086 -0.1348 0.0200" rgba="0 1 0 0.5" /><geom name="col_part_1_7_106" type="sphere" size="0.001" pos="0.0057 -0.1390 0.0197" rgba="0 1 0 0.5" /><geom name="col_part_1_7_107" type="sphere" size="0.001" pos="0.0031 -0.1429 0.0194" rgba="0 1 0 0.5" /><geom name="col_part_1_7_108" type="sphere" size="0.001" pos="0.0007 -0.1469 0.0190" rgba="0 1 0 0.5" /></body>
        </body>
      </body>
      <body name="part_1_8" pos="0.105834 0.109024 -0.00112726" quat="0.973371 -0.165335 0.156542 -0.0265898">
        <inertial pos="0.030927 0.0404396 -0.0201979" quat="0.523111 0.697014 0.00908574 -0.490351" mass="0.139372" diaginertia="0.000187026 0.000186955 2.8107e-05" />
        <joint limited="true" name="sh_roll_3" pos="0 0 0" axis="0 0 1" range="-2.22029 2.10813" />
        <geom pos="0.592033 -1.29728 0.863499" quat="1.20631e-06 0.909188 0.416385 5.52458e-07" type="mesh" rgba="0.25098 0.25098 0.25098 1" mesh="part_1__2" contype="0" conaffinity="0" />
        <body name="part_1_9" pos="0.0793927 0.0656901 -0.0172" quat="0.642892 -0.642894 -0.294429 0.294428">
          <inertial pos="-0.0182232 -0.0776363 0.0184042" quat="0.705732 0.707663 -0.0267869 0.0209295" mass="0.191635" diaginertia="0.000252901 0.000249902 5.35798e-05" />
          <joint limited="true" name="sh_yaw_3" pos="0 0 0" axis="0 0 1" range="-0.00192597 3.00877" />
          <geom pos="0.921634 0.539587 1.34578" quat="9.05808e-07 0.682704 -0.730695 -9.69483e-07" type="mesh" rgba="0.25098 0.25098 0.25098 1" mesh="part_1__3" contype="0" conaffinity="0" />
          <body name="part_1_10" pos="-0.00849973 -0.125011 -0.0007" quat="0.211057 0 0 0.977474">
            <inertial pos="-0.0181801 -0.0523088 0.0189022" quat="0.706958 0.706995 -0.0135554 -0.0135832" mass="0.0518909" diaginertia="5.929e-05 5.27497e-05 1.31167e-05" />
            <joint limited="true" name="kn_yaw_3" pos="0 0 0" axis="0 0 1" range="-1.86497 0.0123759" />
            <geom pos="0 0 -0.004" quat="1 0 0 0" type="mesh" rgba="0.25098 0.25098 0.25098 1" mesh="part_1__4" contype="0" conaffinity="0" />
          <geom name="col_part_1_10_3" type="sphere" size="0.001" pos="-0.0008 -0.1499 0.0188" rgba="0 1 0 0.5" /><geom name="col_part_1_10_7" type="sphere" size="0.001" pos="-0.0005 -0.1500 0.0195" rgba="0 1 0 0.5" /><geom name="col_part_1_10_8" type="sphere" size="0.001" pos="-0.0004 -0.1500 0.0195" rgba="0 1 0 0.5" /><geom name="col_part_1_10_15" type="sphere" size="0.001" pos="0.0059 -0.1337 0.0210" rgba="0 1 0 0.5" /><geom name="col_part_1_10_16" type="sphere" size="0.001" pos="0.0043 -0.1377 0.0205" rgba="0 1 0 0.5" /><geom name="col_part_1_10_17" type="sphere" size="0.001" pos="0.0024 -0.1416 0.0199" rgba="0 1 0 0.5" /><geom name="col_part_1_10_18" type="sphere" size="0.001" pos="0.0008 -0.1453 0.0193" rgba="0 1 0 0.5" /><geom name="col_part_1_10_19" type="sphere" size="0.001" pos="-0.0005 -0.1492 0.0186" rgba="0 1 0 0.5" /><geom name="col_part_1_10_26" type="sphere" size="0.001" pos="-0.0289 0.0006 -0.0039" rgba="0 1 0 0.5" /><geom name="col_part_1_10_30" type="sphere" size="0.001" pos="0.0007 -0.1457 0.0196" rgba="0 1 0 0.5" /><geom name="col_part_1_10_32" type="sphere" size="0.001" pos="0.0004 -0.1467 0.0193" rgba="0 1 0 0.5" /><geom name="col_part_1_10_34" type="sphere" size="0.001" pos="-0.0000 -0.1479 0.0189" rgba="0 1 0 0.5" /><geom name="col_part_1_10_36" type="sphere" size="0.001" pos="-0.0004 -0.1490 0.0186" rgba="0 1 0 0.5" /><geom name="col_part_1_10_85" type="sphere" size="0.001" pos="-0.0301 -0.0233 -0.0036" rgba="0 1 0 0.5" /><geom name="col_part_1_10_86" type="sphere" size="0.001" pos="-0.0301 -0.0244 0.0411" rgba="0 1 0 0.5" /><geom name="col_part_1_10_87" type="sphere" size="0.001" pos="-0.0292 0.0006 0.0418" rgba="0 1 0 0.5" /><geom name="col_part_1_10_90" type="sphere" size="0.001" pos="-0.0005 -0.1494 0.0184" rgba="0 1 0 0.5" /><geom name="col_part_1_10_91" type="sphere" size="0.001" pos="-0.0006 -0.1496 0.0184" rgba="0 1 0 0.5" /><geom name="col_part_1_10_92" type="sphere" size="0.001" pos="-0.0005 -0.1500 0.0195" rgba="0 1 0 0.5" /></body>
        <geom name="col_part_1_9_14" type="sphere" size="0.001" pos="0.0073 0.0053 -0.0022" rgba="0 1 0 0.5" /><geom name="col_part_1_9_27" type="sphere" size="0.001" pos="-0.0590 -0.0792 0.0125" rgba="0 1 0 0.5" /><geom name="col_part_1_9_28" type="sphere" size="0.001" pos="-0.0595 -0.0794 0.0123" rgba="0 1 0 0.5" /><geom name="col_part_1_9_74" type="sphere" size="0.001" pos="-0.0269 -0.1430 0.0399" rgba="0 1 0 0.5" /><geom name="col_part_1_9_75" type="sphere" size="0.001" pos="-0.0270 -0.1435 0.0400" rgba="0 1 0 0.5" /></body>
      <geom name="col_part_1_8_9" type="sphere" size="0.001" pos="0.0454 0.0842 -0.0425" rgba="0 1 0 0.5" /><geom name="col_part_1_8_10" type="sphere" size="0.001" pos="0.0454 0.0843 -0.0426" rgba="0 1 0 0.5" /><geom name="col_part_1_8_13" type="sphere" size="0.001" pos="0.0805 0.0750 -0.0259" rgba="0 1 0 0.5" /><geom name="col_part_1_8_45" type="sphere" size="0.001" pos="0.0734 0.0587 -0.0419" rgba="0 1 0 0.5" /><geom name="col_part_1_8_46" type="sphere" size="0.001" pos="0.0718 0.0571 -0.0420" rgba="0 1 0 0.5" /><geom name="col_part_1_8_47" type="sphere" size="0.001" pos="0.0302 0.0162 -0.0394" rgba="0 1 0 0.5" /><geom name="col_part_1_8_48" type="sphere" size="0.001" pos="0.0301 0.0164 -0.0396" rgba="0 1 0 0.5" /><geom name="col_part_1_8_49" type="sphere" size="0.001" pos="0.0053 -0.0078 -0.0372" rgba="0 1 0 0.5" /><geom name="col_part_1_8_53" type="sphere" size="0.001" pos="0.0031 -0.0089 -0.0372" rgba="0 1 0 0.5" /><geom name="col_part_1_8_96" type="sphere" size="0.001" pos="0.0445 0.0840 -0.0424" rgba="0 1 0 0.5" /><geom name="col_part_1_8_97" type="sphere" size="0.001" pos="-0.0114 0.0237 -0.0395" rgba="0 1 0 0.5" /><geom name="col_part_1_8_98" type="sphere" size="0.001" pos="-0.0114 0.0236 -0.0395" rgba="0 1 0 0.5" /></body>
      <body name="part_1_11" pos="-0.0639141 0.109024 -0.00112726" quat="0.344134 -0.207508 0.0937099 0.910895">
        <inertial pos="0.0508216 0.00300079 -0.0201979" quat="0.28265 0.663346 0.272142 0.637197" mass="0.139372" diaginertia="0.000187026 0.000186955 2.81071e-05" />
        <joint limited="true" name="sh_roll_4" pos="0 0 0" axis="0 0 1" range="-2.2539 2.0686" />
        <geom pos="-0.595484 -1.2957 0.863499" quat="1.32679e-06 1 0 0" type="mesh" rgba="0.25098 0.25098 0.25098 1" mesh="part_1__2" contype="0" conaffinity="0" />
        <body name="part_1_12" pos="0.1016 -0.0172 -0.0172" quat="0.707105 -0.707108 0 0">
          <inertial pos="-0.0174934 -0.077804 0.0184042" quat="0.705627 0.70778 -0.0234651 0.024243" mass="0.191635" diaginertia="0.000252901 0.000249902 5.35797e-05" />
          <joint limited="true" name="sh_yaw_4" pos="0 0 0" axis="0 0 1" range="-0.00288512 3.0168" />
          <geom pos="0.916527 0.548217 1.34578" quat="9.10349e-07 0.686127 -0.727482 -9.6522e-07" type="mesh" rgba="0.25098 0.25098 0.25098 1" mesh="part_1__3" contype="0" conaffinity="0" />
          <body name="part_1_13" pos="-0.00732563 -0.125086 -0.0007" quat="0.686127 0 0 -0.727482">
            <inertial pos="-0.0422016 0.0358574 0.0189022" quat="0.590971 0.590956 0.38826 0.388304" mass="0.0518909" diaginertia="5.929e-05 5.27497e-05 1.31167e-05" />
            <joint limited="true" name="kn_yaw_4" pos="0 0 0" axis="0 0 1" range="-1.84416 0.0207427" />
            <geom pos="0 0 -0.004" quat="0.565052 0 0 -0.825055" type="mesh" rgba="0.25098 0.25098 0.25098 1" mesh="part_1__4" contype="0" conaffinity="0" />
          <geom name="col_part_1_13_4" type="sphere" size="0.001" pos="-0.1391 0.0544 0.0184" rgba="0 1 0 0.5" /><geom name="col_part_1_13_5" type="sphere" size="0.001" pos="-0.1394 0.0545 0.0184" rgba="0 1 0 0.5" /><geom name="col_part_1_13_6" type="sphere" size="0.001" pos="-0.1396 0.0546 0.0183" rgba="0 1 0 0.5" /><geom name="col_part_1_13_37" type="sphere" size="0.001" pos="-0.1385 0.0541 0.0189" rgba="0 1 0 0.5" /><geom name="col_part_1_13_38" type="sphere" size="0.001" pos="-0.1390 0.0545 0.0189" rgba="0 1 0 0.5" /><geom name="col_part_1_13_39" type="sphere" size="0.001" pos="-0.1395 0.0550 0.0188" rgba="0 1 0 0.5" /><geom name="col_part_1_13_44" type="sphere" size="0.001" pos="-0.1397 0.0542 0.0182" rgba="0 1 0 0.5" /><geom name="col_part_1_13_59" type="sphere" size="0.001" pos="-0.0738 0.0536 0.0076" rgba="0 1 0 0.5" /><geom name="col_part_1_13_60" type="sphere" size="0.001" pos="-0.0672 0.0529 0.0064" rgba="0 1 0 0.5" /><geom name="col_part_1_13_61" type="sphere" size="0.001" pos="-0.0576 0.0514 0.0048" rgba="0 1 0 0.5" /><geom name="col_part_1_13_62" type="sphere" size="0.001" pos="-0.0416 0.0475 0.0020" rgba="0 1 0 0.5" /><geom name="col_part_1_13_63" type="sphere" size="0.001" pos="-0.0343 0.0453 0.0007" rgba="0 1 0 0.5" /><geom name="col_part_1_13_64" type="sphere" size="0.001" pos="-0.0261 0.0425 -0.0007" rgba="0 1 0 0.5" /><geom name="col_part_1_13_65" type="sphere" size="0.001" pos="-0.0219 0.0410 -0.0015" rgba="0 1 0 0.5" /><geom name="col_part_1_13_66" type="sphere" size="0.001" pos="-0.0219 0.0411 -0.0015" rgba="0 1 0 0.5" /><geom name="col_part_1_13_67" type="sphere" size="0.001" pos="-0.0165 0.0389 0.0100" rgba="0 1 0 0.5" /><geom name="col_part_1_13_68" type="sphere" size="0.001" pos="-0.0172 0.0392 0.0245" rgba="0 1 0 0.5" /><geom name="col_part_1_13_69" type="sphere" size="0.001" pos="-0.0157 0.0386 0.0293" rgba="0 1 0 0.5" /><geom name="col_part_1_13_70" type="sphere" size="0.001" pos="-0.0118 0.0369 0.0411" rgba="0 1 0 0.5" /><geom name="col_part_1_13_71" type="sphere" size="0.001" pos="-0.0240 0.0418 0.0390" rgba="0 1 0 0.5" /><geom name="col_part_1_13_72" type="sphere" size="0.001" pos="-0.0108 0.0366 0.0414" rgba="0 1 0 0.5" /><geom name="col_part_1_13_73" type="sphere" size="0.001" pos="0.0111 0.0271 0.0418" rgba="0 1 0 0.5" /><geom name="col_part_1_13_78" type="sphere" size="0.001" pos="-0.1268 0.0421 0.0224" rgba="0 1 0 0.5" /><geom name="col_part_1_13_79" type="sphere" size="0.001" pos="-0.1300 0.0453 0.0215" rgba="0 1 0 0.5" /><geom name="col_part_1_13_80" type="sphere" size="0.001" pos="-0.1328 0.0483 0.0206" rgba="0 1 0 0.5" /><geom name="col_part_1_13_81" type="sphere" size="0.001" pos="-0.1356 0.0512 0.0197" rgba="0 1 0 0.5" /><geom name="col_part_1_13_82" type="sphere" size="0.001" pos="-0.1384 0.0539 0.0187" rgba="0 1 0 0.5" /><geom name="col_part_1_13_113" type="sphere" size="0.001" pos="-0.1320 0.0485 0.0192" rgba="0 1 0 0.5" /><geom name="col_part_1_13_114" type="sphere" size="0.001" pos="-0.1339 0.0501 0.0191" rgba="0 1 0 0.5" /><geom name="col_part_1_13_115" type="sphere" size="0.001" pos="-0.1357 0.0516 0.0190" rgba="0 1 0 0.5" /><geom name="col_part_1_13_116" type="sphere" size="0.001" pos="-0.1372 0.0530 0.0189" rgba="0 1 0 0.5" /></body>
        </body>
      </body>
    </body>
  </worldbody>

  <actuator>
    
    <motor name="sh_roll_1_motor" joint="sh_roll_1" gear="3" ctrlrange="-10 10" />
    <motor name="sh_yaw_1_motor" joint="sh_yaw_1" gear="3" ctrlrange="-10 10" />
    <motor name="kn_yaw_1_motor" joint="kn_yaw_1" gear="3" ctrlrange="-10 10" />
    
    
    <motor name="sh_roll_2_motor" joint="sh_roll_2" gear="3" ctrlrange="-10 10" />
    <motor name="sh_yaw_2_motor" joint="sh_yaw_2" gear="3" ctrlrange="-10 10" />
    <motor name="kn_yaw_2_motor" joint="kn_yaw_2" gear="3" ctrlrange="-10 10" />
    
    
    <motor name="sh_roll_3_motor" joint="sh_roll_3" gear="3" ctrlrange="-10 10" />
    <motor name="sh_yaw_3_motor" joint="sh_yaw_3" gear="3" ctrlrange="-10 10" />
    <motor name="kn_yaw_3_motor" joint="kn_yaw_3" gear="3" ctrlrange="-10 10" />
    
    
    <motor name="sh_roll_4_motor" joint="sh_roll_4" gear="3" ctrlrange="-10 10" />
    <motor name="sh_yaw_4_motor" joint="sh_yaw_4" gear="3" ctrlrange="-10 10" />
    <motor name="kn_yaw_4_motor" joint="kn_yaw_4" gear="3" ctrlrange="-10 10" />
  </actuator>
</mujoco>